Workbook
Name ClientList: '_FilterLists'!$B$1:$B$48
Name SubCategoryList: '_FilterLists'!$A$1:$A$28

Sheet _FilterLists
A1: All | B1: All
A2: Access control/CCTV/Security System | B2: Algoworks
A3: Animal Movement | B3: Alight Solutions
A4: Carpentry | B4: Alphagrep Securities
A5: Civil | B5: Apcer Life Sciences India Limited
A6: Cleaning | B6: Atkins
A7: Compliance and Policy Violations | B7: BAYSTREET ADVISORS PRIVATE LIMITED
A8: Drinking water | B8: Baker Hughes
A9: Electrical | B9: Bayer
A10: Ergonomic Impacts | B10: Brillio
A11: Food & Beverages | B11: CBRE D&T
A12: HVAC | B12: Centrient Pharma
... A28: Workplace Violence | B28: Nimbuspay Innovations India Private Limited
B29: PWC - Pricewaterhouse Cooper Pvt. Ltd.
B30: PricewaterhouseCoopers Service Delivery Center (Kolkata) Private Limited
B31: Pubmatic
B32: ROHM SEMICONDUCTOR INDIA PRIVATE LIMITED
B33: SSandC
B34: Sainsbury's
B35: Siemens
B36: Table Space
B37: Teleflex
B38: Thermofisher
B39: Topsoe India Private Limited
B40: Tresvista
... B48: Zelestra

Sheet Dashboard
B1: 📊 Client Tracker NCR - Dashboard
B2: Incident Management & Client Overview | Use dropdown filters below to analyze data
B4: 🏙 City | C4: 🏢 Facility | D4: 📅 Month | E4: 📂 Category | F4: 🔧 Sub-Category | G4: 🚦 Status | H4: 👥 Client | I4: ⚠️ Business Impact | J4: ⏳ Bucket | K4: 📅 From Date | L4: 📅 To Date
B5: All | C5: All | D5: All | E5: All | F5: All | G5: All | H5: All | I5: All | J5: All
B6: ⬆️ Use the dropdown filters above to filter data. Select "All" to show everything. Enter dates in From/To Date cells for date range filtering. Charts and formulas update when you open the file in Excel.
B8: TOTAL INCIDENTS | D8: OPEN | F8: CLOSED | H8: IN PROGRESS | J8: BUSINESS IMPACT | L8: UNIQUE SITES
B9: ='Dashboard Formula (Reference)'!B2 -> 355 | D9: ='Dashboard Formula (Reference)'!B3 -> 5 | F9: ='Dashboard Formula (Reference)'!B4 -> 348 | H9: ='Dashboard Formula (Reference)'!B5 -> 2 | J9: ='Dashboard Formula (Reference)'!B6 -> 99 | L9: ='Dashboard Formula (Reference)'!B7 -> 11

Sheet Dashboard Formula (Reference)
A1: KPI Metric | B1: Count | D1: Category | E1: Count | G1: Month | H1: Count | J1: Status | K1: Count | M1: City | N1: Count
A2: Total Incidents | B2: =COUNTA(Incidents!H2:H356) -> 355 | D2: Engineering & Building Services | E2: =COUNTIF(Incidents!L2:L356,D2) -> 218 | G2: Nov'24 | H2: =COUNTIF(Incidents!D2:D356,G2) -> 17 | J2: Open | K2: =COUNTIF(Incidents!R2:R356,J2) -> 5 | M2: Gurugram | N2: =COUNTIF(Incidents!A2:A356,M2) -> 237
A3: Open | B3: =COUNTIF(Incidents!R2:R356,"Open") -> 5 | D3: Security | E3: =COUNTIF(Incidents!L2:L356,D3) -> 61 | G3: Dec'24 | H3: =COUNTIF(Incidents!D2:D356,G3) -> 24 | J3: In Progress | K3: =COUNTIF(Incidents!R2:R356,J3) -> 2 | M3: Noida | N3: =COUNTIF(Incidents!A2:A356,M3) -> 118
A4: Closed | B4: =COUNTIF(Incidents!R2:R356,"Closed") -> 348 | D4: Operations | E4: =COUNTIF(Incidents!L2:L356,D4) -> 28 | G4: Jan'25 | H4: =COUNTIF(Incidents!D2:D356,G4) -> 26 | J4: Closed | K4: =COUNTIF(Incidents!R2:R356,J4) -> 348
A5: In Progress | B5: =COUNTIF(Incidents!R2:R356,"In Progress") -> 2 | D5: Health & Safety | E5: =COUNTIF(Incidents!L2:L356,D5) -> 25 | G5: Feb'25 | H5: =COUNTIF(Incidents!D2:D356,G5) -> 24
A6: Business Impact (Yes) | B6: =COUNTIF(Incidents!O2:O356,"Yes") -> 99 | D6: Others | E6: =COUNTIF(Incidents!L2:L356,D6) -> 21 | G6: Mar'25 | H6: =COUNTIF(Incidents!D2:D356,G6) -> 16
A7: Unique Sites | B7: =SUMPRODUCT(1/COUNTIF(Incidents!B2:B356,Incidents!B2:B356)) -> 11 | D7: Traffic & Transport | E7: =COUNTIF(Incidents!L2:L356,D7) -> 2 | G7: Apr'25 | H7: =COUNTIF(Incidents!D2:D356,G7) -> 19
G8: May'25 | H8: =COUNTIF(Incidents!D2:D356,G8) -> 13
G9: Jun'25 | H9: =COUNTIF(Incidents!D2:D356,G9) -> 12
A10: Business Impact | B10: Count | D10: Aging Bucket | E10: Count | G10: Facility | H10: Count | J10: Sub-Category | K10: Count
A11: Yes | B11: =COUNTIF(Incidents!O2:O356,A11) -> 99 | D11: 0 - 5 Days | E11: =COUNTIF(Incidents!F2:F356,D11) -> 2 | G11: DLF 10 B&C | H11: =COUNTIF(Incidents!B2:B356,G11) -> 120 | J11: Electrical | K11: =COUNTIF(Incidents!M2:M356,J11) -> 62
A12: No | B12: =COUNTIF(Incidents!O2:O356,A12) -> 256 | D12: 5 - 10 Days | E12: =COUNTIF(Incidents!F2:F356,D12) -> 3 | G12: Capital City BPTP | H12: =COUNTIF(Incidents!B2:B356,G12) -> 89 | J12: Safety security systems | K12: =COUNTIF(Incidents!M2:M356,J12) -> 49
D13: 10 - 20 Days | E13: =COUNTIF(Incidents!F2:F356,D13) -> 9 | G13: Cyber Green | H13: =COUNTIF(Incidents!B2:B356,G13) -> 53 | J13: Plumbing | K13: =COUNTIF(Incidents!M2:M356,J13) -> 39
D14: 20 - 30 Days | E14: =COUNTIF(Incidents!F2:F356,D14) -> 9 | G14: DLF Tech Park | H14: =COUNTIF(Incidents!B2:B356,G14) -> 29 | J14: Access control/CCTV/Security System | K14: =COUNTIF(Incidents!M2:M356,J14) -> 23
D15: 30 + Days | E15: =COUNTIF(Incidents!F2:F356,D15) -> 332 | G15: DLF Downtown - Gurgaon | H15: =COUNTIF(Incidents!B2:B356,G15) -> 21 | J15: Medical Emergencies | K15: =COUNTIF(Incidents!M2:M356,J15) -> 18
G16: Two Horizon | H16: =COUNTIF(Incidents!B2:B356,G16) -> 17 | J16: Others | K16: =COUNTIF(Incidents!M2:M356,J16) -> 17
G17: DLF 8 | H17: =COUNTIF(Incidents!B2:B356,G17) -> 14 | J17: Compliance and Policy Violations | K17: =COUNTIF(Incidents!M2:M356,J17) -> 16
G18: DLF 6 | H18: =COUNTIF(Incidents!B2:B356,G18) -> 7 | J18: HVAC | K18: =COUNTIF(Incidents!M2:M356,J18) -> 16
G19: Good Earth Business Bay II | H19: =COUNTIF(Incidents!B2:B356,G19) -> 2 | J19: Carpentry | K19: =COUNTIF(Incidents!M2:M356,J19) -> 14
G20: Global Gateway | H20: =COUNTIF(Incidents!B2:B356,G20) -> 2 | J20: Others (Engineering) | K20: =COUNTIF(Incidents!M2:M356,J20) -> 13
G21: DLF 5 A | H21: =COUNTIF(Incidents!B2:B356,G21) -> 1 | J21: Food & Beverages | K21: =COUNTIF(Incidents!M2:M356,J21) -> 11
J22: Civil | K22: =COUNTIF(Incidents!M2:M356,J22) -> 11
J23: Security System Incidents | K23: =COUNTIF(Incidents!M2:M356,J23) -> 7
J24: Drinking water | K24: =COUNTIF(Incidents!M2:M356,J24) -> 6
J25: Theft or Loss | K25: =COUNTIF(Incidents!M2:M356,J25) -> 6
J26: Pest Control | K26: =COUNTIF(Incidents!M2:M356,J26) -> 5
J27: Unauthorized Access | K27: =COUNTIF(Incidents!M2:M356,J27) -> 5
J28: Workplace Violence | K28: =COUNTIF(Incidents!M2:M356,J28) -> 4
J29: Harm to People | K29: =COUNTIF(Incidents!M2:M356,J29) -> 3
J30: Animal Movement | K30: =COUNTIF(Incidents!M2:M356,J30) -> 2
J31: Housekeeping | K31: =COUNTIF(Incidents!M2:M356,J31) -> 2
J32: Natural Disasters | K32: =COUNTIF(Incidents!M2:M356,J32) -> 2
J33: Other | K33: =COUNTIF(Incidents!M2:M356,J33) -> 1
J34: Restroom Cleaning | K34: =COUNTIF(Incidents!M2:M356,J34) -> 1
J35: Cleaning | K35: =COUNTIF(Incidents!M2:M356,J35) -> 1
J36: Vehicle Damage | K36: =COUNTIF(Incidents!M2:M356,J36) -> 1
J37: Ergonomic Impacts | K37: =COUNTIF(Incidents!M2:M356,J37) -> 1

Sheet Client MOM
A1: Location | B1: Site Name | C1: Client Name | D1: Client Category | E1: TS Suites / TS Managed | F1: Floor Details | G1: On-going Issues | H1: Appreciation | I1: Sales Expansion
A2: Noida | B2: Capital City BPTP | C2: Clearwater Analytics | D2: Diamond | E2: TS Managed | F2: 10 | G2: 1. Lux level need to be increased on workstation area.
A3: Noida | B3: Capital City BPTP | C3: Clearwater Analytics | D3: Diamond | E3: TS Managed | F3: 10 | G3: 2. Faulty Lock to be replace.
A4: Noida | B4: Capital City BPTP | C4: Clearwater Analytics | D4: Diamond | E4: TS Managed | F4: 10 | G4: 3. Paint to be done at highlighted areas.
A5: Noida | B5: Capital City BPTP | C5: DSV | E5: TS Managed | F5: BPTP Capital City 11th Floor | G5: 1. Gypsum cracks need to be re-filled & paint touch required in entire office area.
A6: Noida | B6: Capital City BPTP | C6: Dedalus | E6: TS Managed | F6: BPTP Capital City 12th Floor | G6: 1. Main Door frame need to be replace with new one.
A7: Noida | B7: Capital City BPTP | C7: Dedalus | E7: TS Managed | F7: BPTP Capital City 12th Floor | G7: 2. Internet issue to be resolved.
A8: Noida | B8: Capital City BPTP | C8: IBM | E8: TS Managed | F8: BPTP Capital City 12th Floor
A9: Noida | B9: Capital City BPTP | C9: Siemens | E9: TS Managed | F9: BPTP Capital City 12th Floor | G9: 1. Invoices pertaining to chargeback to be share on timely basis.
A10: Noida | B10: Capital City BPTP | C10: Siemens | E10: TS Managed | F10: BPTP Capital City 12th Floor | G10: 2. Housekeeping services to be improved.
A11: Noida | B11: Capital City BPTP | C11: Siemens | E11: TS Managed | F11: BPTP Capital City 12th Floor | G11: 3. Pantry floor mat to be replace.
A12: Noida | B12: Capital City BPTP | C12: Thermofisher | E12: TS Suites | F12: BPTP Capital City 13th Floor | G12: 1. Cleaning to be maintain on a regular basis.
A13: Noida | B13: Capital City BPTP | C13: Voya | E13: TS Suites | F13: BPTP Capital City 13th Floor | G13: 1. Coffee machine Breakdown.
A14: Noida | B14: Capital City BPTP | C14: Voya | E14: TS Suites | F14: BPTP Capital City 13th Floor | G14: 2. Pantry staff to be available in late night hours.
A15: Noida | B15: Capital City BPTP | C15: Atkins | E15: TS Suites | F15: BPTP Capital City 15th Floor | G15: 1. Internet services to be improve.
A16: Noida | B16: Capital City BPTP | C16: CBRE D&T | E16: TS Managed / TS Suites | F16: BPTP Capital City 15th Floor
A17: Noida | B17: Capital City BPTP | C17: Dayforce | E17: TS Managed | F17: BPTP Capital City 15th Floor | G17: 1. Drinking water RO to be maintained under AMC.
A18: Noida | B18: Capital City BPTP | C18: Dayforce | E18: TS Managed | F18: BPTP Capital City 15th Floor | G18: 2. Housekeeping service to be maintained.
A19: Noida | B19: Capital City BPTP | C19: Nimbuspay Innovations | E19: TS Managed | F19: BPTP Capital City 15th Floor | H19: "Hi Lipin, Rohit, I hope you’re doing well. I would like to take a moment to sincerely thank Pushpendra and his team for their exceptional support and service. I would especially like to acknowledge Pushpendra for his kind, considerate, and attentive approach. He is extremely proactive and always a call away, played a significant role in ensuring the smooth management of our client visit. Thank you once again for your dedication and outstanding support. 😊 With Regards Isha Saxena Sr. VP- Human Resource 8800940017 Nimbuspay Technologies Inc. "
A20: Noida | B20: Capital City BPTP | C20: Switchfly | E20: TS Suites | F20: BPTP Capital City 15th Floor | G20: 1. GST Plate & Frosting work to be completed on chargeback cost.
A21: Noida | B21: Capital City BPTP | C21: Teleflex | E21: TS Suites | F21: BPTP Capital City 15th Floor | G21: 1. Pantry operations to be monitored.
A22: Noida | B22: Capital City BPTP | C22: Apcer | E22: TS Managed | F22: BPTP Capital City 9th Floor
A23: Noida | B23: Capital City BPTP | C23: Naviga | E23: TS Managed | F23: BPTP Capital City 9th Floor | G23: 1 Pantries to be set properly every morning.
A24: Noida | B24: Capital City BPTP | C24: Rohm Semiconductor India Private Limited | E24: TS Managed | F24: BPTP Capital City 9th Floor
A25: Gurugram | B25: DLF 6 | C25: ETS | E25: TS Managed | F25: DLF 6, 4th floor | G25: Project Related Issues 1. Negative Air pressure due to which doors are not closing properly
A26: Gurugram | B26: DLF 10 B&C | C26: Baker Hughes | E26: TS Managed | F26: DLF Cyber City 10B&C, 10th floor
A27: Gurugram | B27: DLF 10 B&C | C27: Berkadia | E27: TS Managed | F27: DLF Cyber City 10B&C, 10th floor | G27: Housekeeping issues due to staff scarcity during B-Shift
A28: Gurugram | B28: DLF 10 B&C | C28: Centrient Pharma | E28: TS Managed | F28: DLF Cyber City 10B&C, 10th floor | G28: 1. Pest Control
A29: Gurugram | B29: DLF 10 B&C | C29: Centrient Pharma | E29: TS Managed | F29: DLF Cyber City 10B&C, 10th floor | G29: 2. Housekeeping
A30: Gurugram | B30: DLF 10 B&C | C30: Centrient Pharma | E30: TS Managed | F30: DLF Cyber City 10B&C, 10th floor | G30: 3. Pantry Services
A31: Gurugram | B31: DLF 10 B&C | C31: Centrient Pharma | E31: TS Managed | F31: DLF Cyber City 10B&C, 10th floor | G31: 4. Coffee Machine Breakdown
A32: Gurugram | B32: DLF 10 B&C | C32: Centrient Pharma | E32: TS Managed | F32: DLF Cyber City 10B&C, 10th floor | G32: 5. Housekeeping issues due to staff scarcity during B-Shift
A33: Gurugram | B33: DLF 10 B&C | C33: NTT India Private Limited | E33: TS Managed | F33: DLF Cyber City 10B&C, 10th floor | G33: 1. WC Blocakge Issue
A34: Gurugram | B34: DLF 10 B&C | C34: NTT India Private Limited | E34: TS Managed | F34: DLF Cyber City 10B&C, 10th floor | G34: 2. Linear Light Faulty
A35: Gurugram | B35: DLF 10 B&C | C35: NTT India Private Limited | E35: TS Managed | F35: DLF Cyber City 10B&C, 10th floor | G35: 3. Pantry Cupboard need to be fixed
A36: Gurugram | B36: DLF 10 B&C | C36: NTT India Private Limited | E36: TS Managed | F36: DLF Cyber City 10B&C, 10th floor | G36: 4. Housekeeping issues due to staff scarcity during B-Shift
A37: Gurugram | B37: DLF 10 B&C | C37: Pubmatic | E37: TS Managed | F37: DLF Cyber City 10B&C, 10th floor | G37: 1. Coffee Machine Breakdown
A38: Gurugram | B38: DLF 10 B&C | C38: Pubmatic | E38: TS Managed | F38: DLF Cyber City 10B&C, 10th floor | G38: 2. CCTV Footage access on their domain
... A45: Gurugram | B45: DLF 10 B&C | C45: Vialto | E45: TS Managed | F45: DLF Cyber City 10B&C, 2nd floor | G45: 3. Unauthorized parking Issue
A46: Gurugram | B46: DLF 10 B&C | C46: Graviton | E46: TS Managed | F46: DLF Cyber City 10B&C, 3rd floor
...

Sheet Incidents
A1: City | B1: Facility | C1: Date | D1: Month | E1: Pending since | F1: Bucket | G1: Closure Status | H1: ID | I1: Request # | J1: Client | K1: Location | L1: Category | M1: Sub-Category | N1: Time Of Occurrence | O1: Business Impact | P1: Description Of Incident | Q1: Corrective Action | R1: Status | S1: Created By | T1: Created At | U1: Updated By | V1: Updated At
A2: Gurugram | B2: DLF Downtown - Gurgaon | C2: 09-Mar-26 | D2: Mar'26 | E2: 2 | F2: 0 - 5 Days | G2: 0 | H2: 2412 | I2: INC_DT16_TBS_2412 | J2: Table Space | K2: DLF Downtown - Block 4, Gurugram, 16th Floor | L2: Engineering & Building Services | M2: Electrical | N2: 46090.438 | O2: No | P2: What: The server room drain pump stopped working automatically. Due to this, water leakage started from the AC unit and the WLD alarm was activated. REQUESTER - Priyanka Malhotra | Q2: 1. Checked and cleaned the drain tray to remove any dirt, debris, or blockage that was preventing the smooth flow of condensate water. 2.Inspected the drain pump float switch and ensured it was free from obstruction. The float mechanism was reset to enable proper automatic operation. 3.Tested the pump operation in manual and auto modes to confirm functionality and ensure the pump restarts automatically when the water level rises.4.Verified electrical connections and control wiring to eliminate any loose contacts or relay issues.5.Conducted a run test to confirm that condensate water is being pumped out efficiently, with no further accumulation or leakage.6 Monitored the AC unit and WLD panel after restoration to ensure stability and normal operating conditions. - Close | R2: Closed | S2: Ravi | T2: 46090.512 | U2: Ravi | V2: 46090.512
A3: Gurugram | B3: Cyber Green | C3: 09-Mar-26 | D3: Mar'26 | E3: 2 | F3: 0 - 5 Days | G3: 1 | H3: 2407 | I3: INC_DLFCG8_TBS_2407 | J3: Wood Mackenzie | K3: DLF Cyber Greens - Tower D & E, 8th Floor | L3: Engineering & Building Services | M3: Electrical | N3: 46090.375 | O3: No | P3: What: - Cafeteria CSU unit balt broken issue. REQUESTER - Sanjay Kumar | R3: Open | S3: Ravi | T3: 46090.401 | U3: Ravi | V3: 46090.401
A4: Noida | B4: Capital City BPTP | C4: 05-Mar-26 | D4: Mar'26 | E4: 6 | F4: 5 - 10 Days | G4: 1 | H4: 2391 | I4: INC_BPTPCC_TBS_2391 | J4: ZS Associates | K4: BPTP Capital City | L4: Engineering & Building Services | M4: Safety security systems | N4: 46086.618 | O4: No | P4: What: A6 alarm is displayed on the thermostat of the server room unit. How: The alarm was triggered due to a communication error between the indoor and outdoor units. REQUESTER - Vishwajeet Kumar | Q4: The vendor has been aligned to check the issue with the indoor unit. The vendor visited the site and observed that an A6 alarm is being displayed on the thermostat due to a faulty PCB card. The PCB card has been sent for repair by the AMC vendor partner. They have confirmed that the faulty card will be replaced by maximum tomorrow. - Inprogress | R4: In Progress | S4: Ravi | T4: 46086.66 | U4: Ravi | V4: 46086.66
A5: Noida | B5: Capital City BPTP | C5: 03-Mar-26 | D5: Mar'26 | E5: 8 | F5: 5 - 10 Days | G5: 0 | H5: 2383 | I5: INC_BPTPCC_TBS_2383 | J5: Naviga | K5: BPTP Capital City | L5: Engineering & Building Services | M5: Electrical | N5: 46084.931 | O5: No | P5: What: 100kVA UPS module fan failure. How: Root Cause Analysis (RCA) is awaited from the vendor. REQUESTER - Vishwajeet Kumar Singh | Q5: We have highlighted the issue to the OEM Team to fixed the issue permanently also same has been brief for Implement during preventive maintenance, including cleaning of UPS internal components and periodic inspection of cooling fans. - Close | R5: Closed | S5: Ravi | T5: 46086.412 | U5: Ravi | V5: 46086.412
A6: Gurugram | B6: Cyber Green | C6: 02-Mar-26 | D6: Mar'26 | E6: 9 | F6: 5 - 10 Days | G6: 0 | H6: 2370 | I6: INC_DLFCG_TBS_2370 | J6: PWC - Pricewaterhouse Cooper Pvt. Ltd. | K6: DLF Cyber Greens - Tower D & E | L6: Engineering & Building Services | M6: Plumbing | N6: 46083.569 | O6: No | P6: What: Water leakage from the sprinkler line. How: Sprinkler joint leakage. REQUESTER - Sonu kumar giri | Q6: We inspected the leakage point and have aligned the project team to resolve the issue. - Close | R6: Closed | S6: Ravi | T6: 46083.653 | U6: Ravi | V6: 46083.653
A7: Noida | B7: DLF Tech Park | C7: 01-Mar-26 | D7: Mar'26 | E7: 10 | F7: 10 - 20 Days | G7: 0 | H7: 2366 | I7: INC_DLFTP5_TBS_2366 | J7: Topsoe India Private Limited | K7: DLF Tech Park, 5th Floor | L7: Engineering & Building Services | M7: Plumbing | N7: 46082.729 | O7: No | P7: What: During a routine inspection, water leakage was noticed from the ceiling on the 5th floor. How: Initial checking shows that the leakage is coming from the 6th floor washroom area, possibly due to a waterproofing problem. REQUESTER - Anoop Singh | Q7: The project team conducted a detailed inspection of the 6th-floor washroom to identify the cause of the leakage, including checking the plumbing lines, floor trap sealing, and waterproofing. The necessary repairs were carried out, damaged parts were replaced, and re-grouting and waterproofing were completed where required. The area has now been properly sealed to prevent further leakage. - Close | R7: Closed | S7: Ravi | T7: 46083.394 | U7: Ravi | V7: 46083.394
A8: Gurugram | B8: DLF Downtown - Gurgaon | C8: 27-Feb-26 | D8: Feb'26 | E8: 12 | F8: 10 - 20 Days | G8: 0 | H8: 2356 | I8: INC_DT16_TBS_2356 | J8: Table Space | K8: DLF Downtown - Block 4, Gurugram, 16th Floor | L8: Security | M8: Workplace Violence | N8: 46080.41 | O8: No | P8: Construction work was in progress at the DT-4 site, and multiple labourers were working in the area. A fight broke out among the labourers. During the incident, a member of the Innovation team named Praveen was assaulted by several labourers. Requester: Priyanka Malhotra | Q8: I immediately sent the security supervisor to the back site area and stopped the fight. Praveen was safely brought to the common area reception, and the site team was informed immediately - Close | R8: Closed | S8: Sree Prabhu | T8: 46080.529 | U8: Sree Prabhu | V8: 46080.529
A9: Gurugram | B9: DLF 10 B&C | C9: 25-Feb-26 | D9: Feb'26 | E9: 14 | F9: 10 - 20 Days | G9: 0 | H9: 2348 | I9: INC_DLF10BF9_TBS_2348 | J9: Circle K | K9: DLF Cyber City 10B&C, 9th floor | L9: Engineering & Building Services | M9: Plumbing | N9: 46078.854 | O9: No | P9: water was found overflowing in the Gents' washroom and Handicapped washroom on the 9th floor. The overflow caused water accumulation on the washroom floor. Requester: Jatin Negi | Q9: The technical team has been informed to check and resolve the issue. The housekeeping team was aligned immediately to clean the affected area and prevent any slip hazards. - Close | R9: Closed | S9: Sree Prabhu | T9: 46079.4 | U9: Sree Prabhu | V9: 46079.4
A10: Noida | B10: DLF Tech Park | C10: 25-Feb-26 | D10: Feb'26 | E10: 14 | F10: 10 - 20 Days | G10: 0 | H10: 2345 | I10: INC_DLFTP6_TBS_2345 | J10: Algoworks | K10: DLF Tech Park, 6th Floor | L10: Engineering & Building Services | M10: Safety security systems | N10: 46078.771 | O10: No | P10: False alarm activated Where: TS common area How: Due to smoke detector malfunctioning Requester: Anoop Sing | Q10: Alarm acknowledges by inhouse team • Team checked and silenced the FAS panel • Visited the location of activation cleaned the smoke detector, and reset the FAS panel • Informed the internal management about the incident • Announcement has been done as per standard speech - Close | R10: Closed | S10: Sree Prabhu | T10: 46079.392 | U10: Sree Prabhu | V10: 46079.392
A11: Gurugram | B11: DLF 10 B&C | C11: 25-Feb-26 | D11: Feb'26 | E11: 14 | F11: 10 - 20 Days | G11: 0 | H11: 2341 | I11: INC_DLFBCC10_TBS_2341 | J11: Table Space | K11: DLF Cyber City - Building No. 10 - Tower B & C, 10th Floor | L11: Engineering & Building Services | M11: Electrical | N11: 46078.542 | O11: No | P11: What: 150 kVA UPS module fan failure. REQUESTER - Sonu Kumar Giri | Q11: We have raised a service ticket and are awaiting the OEM's fan replacement. - Close | R11: Closed | S11: Ravi | T11: 46078.592 | U11: Ravi | V11: 46078.592
A12: Gurugram | B12: Cyber Green | C12: 25-Feb-26 | D12: Feb'26 | E12: 14 | F12: 10 - 20 Days | G12: 0 | H12: 2340 | I12: INC_TBS_2340 | J12: PricewaterhouseCoopers Service Delivery Center (Kolkata) Private Limited | K12: DLF Cyber Greens - Tower D & E, 2nd Floor | L12: Engineering & Building Services | M12: Plumbing | N12: 46078.479 | O12: No | P12: What: Water leakage from ceiling in gent's washroom. How: 3rd floor tower d washroom drain line is blocked. REQUESTER - Yastika Sikka | Q12: The plumber has cleared the drain lines for 3rd floor and water leakage has been resolved for 2nd floor. - Close | R12: Closed | S12: Ravi | T12: 46078.529 | U12: Ravi | V12: 46078.529
A13: Gurugram | B13: Cyber Green | C13: 25-Feb-26 | D13: Feb'26 | E13: 14 | F13: 10 - 20 Days | G13: 0 | H13: 2336 | I13: INC_DLFCG9_TBS_2336 | J13: Brillio | K13: DLF Cyber Greens - Tower D & E, 9th Floor | L13: Operations | M13: Food & Beverages | N13: 46078.354 | O13: No | P13: Coffee machine milk container is overflowing with water Requester: Vishwajeet Kumar | Q13: The vendor has fixed the sensor and the container is working properly now. - Close | R13: Closed | S13: Sree Prabhu | T13: 46078.401 | U13: Sree Prabhu | V13: 46078.401
A14: Noida | B14: Capital City BPTP | C14: 24-Feb-26 | D14: Feb'26 | E14: 15 | F14: 10 - 20 Days | G14: 0 | H14: 2335 | I14: INC_BPTPCC14_TBS_2335 | J14: ZS Associates | K14: BPTP Capital City, 14th Floor | L14: Engineering & Building Services | M14: Electrical | N14: 46077.951 | O14: No | P14: Battery terminal lugs were found damaged. Where : 14th Floor UPS Room How : The issue was identified during a routine inspection of the battery bank. Root Cause Analysis (RCA) is awaited from the OEM vendor. Requester: Vishwajeet Kumar Singh | Q14: The faulty battery terminal lugs have been replaced by the OEM team. All battery terminals have been thoroughly cleaned to remove carbon deposits and corrosion. Proper torque tightening has been carried out strictly as per OEM-recommended standards. Anti-corrosion petroleum jelly / terminal protective grease has been applied to all terminals to prevent future oxidation and corrosion. During future PPM (Planned Preventive Maintenance) visits, we will ensure that: Proper torque tightening is carried out as per OEM specifications. Tightening is done in our presence to avoid any gaps or loose connections. A detailed checklist verification is completed before closure of the activity. We will continue to closely monitor the battery bank condition to prevent recurrence of such issues. have been replaced by the OEM team. All battery terminals have been cleaned properly. Proper torque tightening has been carried out as per OEM standards. Anti-corrosion petroleum jelly / terminal protective grease has been applied.also we have ensured that the OEM team Jab PPM karegi toh usko sahi tarkie se tighneing karayenge aur apne samne karayenge taki koi gap Na ho - Close | R14: Closed | S14: Sree Prabhu | T14: 46078.399 | U14: Sree Prabhu | V14: 46078.399
A15: Noida | B15: Capital City BPTP | C15: 24-Feb-26 | D15: Feb'26 | E15: 15 | F15: 10 - 20 Days | G15: 0 | H15: 2327 | I15: INC_BPTPCC_TBS_2327 | J15: ZS Associates | K15: BPTP Capital City | L15: Engineering & Building Services | M15: Safety security systems | N15: 46077.396 | O15: No | P15: What: False fire alarm activated. How: The smoke detector was triggered due to excessive smoke generated when an associate accidentally over-grilled bread in the pantry area. REQUESTER - Vishwajeet | Q15: The team immediately inspected the fire alarm panel to identify the exact location of activation. The smoke detector was checked and cleaned, and the Fire Alarm System (FAS) panel was reset on the same time,also announcement has been done as TS standard speech.A briefing was conducted with the concerned associate and ZS security personnel to avoid recurrence. also A safety advisory will be circulated to all employees regarding proper use of grilling/toasting equipment and the importance of not leaving appliances unattended. - Close | R15: Closed | S15: Ravi | T15: 46077.43 | U15: Ravi | V15: 46077.43
... A32: Gurugram | B32: DLF 10 B&C | C32: 03-Feb-26 | D32: Feb'26 | E32: 36 | F32: 30 + Days | G32: 0 | H32: 2205 | I32: INC_DLFCC10B14_TBS_2205 | J32: Tresvista | K32: DLF Cyber City 10B&C, 14th Floor | L32: Engineering & Building Services | M32: Others (Engineering) | N32: 46056.715 | O32: Yes | P32: What: PU material leaked from RCC. How: Upon inspection, we have checked the PU is leaking from Terrace. REQUESTER - Abhishek Singh | Q32: we have checked the leakage thoroughly and with the help of DLF team, cleared PU from carpet and Cabin Glass. - Close | R32: Closed | S32: Ravi | T32: 46057.399 | U32: Ravi | V32: 46057.399
A33: Gurugram | B33: DLF 10 B&C | C33: 03-Feb-26 | D33: Feb'26 | E33: 36 | F33: 30 + Days | G33: 1 | H33: 2202 | I33: INC_DLFBCC10_TBS_2202 | J33: Centrient Pharma | K33: DLF Cyber City - Building No. 10 - Tower B & C, 10th Floor | L33: Operations | M33: Pest Control | N33: 46056.646 | O33: No | P33: What: Pest issue was raised by the client. REQUESTER - Gautami Choithwani | R33: Open | S33: Ravi | T33: 46056.706 | U33: Ravi | V33: 46056.706
A34: Gurugram | B34: DLF 10 B&C | C34: 03-Feb-26 | D34: Feb'26 | E34: 36 | F34: 30 + Days | G34: 1 | H34: 2201 | I34: INC_DLFCC10BC_TBS_2201 | J34: Circle K | K34: DLF Cyber City 10B&C | L34: Operations | M34: Pest Control | N34: 46056.618 | O34: No | P34: What: Pest issue was raised by the client in pantry and cafeteria areas. REQUESTER - Gautami Choithwani | R34: Open | S34: Ravi | T34: 46056.694 | U34: Ravi | V34: 46056.694
A35: Gurugram | B35: DLF 10 B&C | C35: 02-Feb-26 | D35: Feb'26 | E35: 37 | F35: 30 + Days | G35: 0 | H35: 2189 | I35: INC_DLF10BF9_TBS_2189 | J35: Circle K | K35: DLF Cyber City 10B&C, 9th floor | L35: Engineering & Building Services | M35: Electrical | N35: 46055 | O35: No | P35: What: ACS is not working. How: Upon inspection, we have checked the SMPS is not working. REQUESTER - Abhishek Singh | Q35: we have checked the SMPS supply and found input voltage is ok but not provided the output voltage. We are aligned the vendor to change the SMPS. - Close | R35: Closed | S35: Ravi | T35: 46055.74 | U35: Ravi | V35: 46055.74
A36: Gurugram | B36: Good Earth Business Bay II | C36: 28-Jan-26 | D36: Jan'26 | E36: 42 | F36: 30 + Days | G36: 0 | H36: 2167 | I36: INC_GOBB23_TBS_2167 | J36: Table Space | K36: Good Earth Business Bay II, 3rd Floor | L36: Engineering & Building Services | M36: Plumbing | N36: 46050.826 | O36: No | P36: What: Geyser outlet pipe is damaged. How: Not specified. REQUESTER - Sonu Kumar Giri | Q36: The in-house team has checked the issue and found the geyser outlet pipe to be damaged. Initially the inhouse team closed the valve to prevent the water leakage and also aligned the project team for replacement of the geyser pipe. - Close | R36: Closed | S36: Ravi | T36: 46051.526 | U36: Ravi | V36: 46051.526
A37: Gurugram | B37: Cyber Green | C37: 29-Jan-26 | D37: Jan'26 | E37: 41 | F37: 30 + Days | G37: 0 | H37: 2163 | I37: INC_DLFCG6_TBS_2163 | J37: PricewaterhouseCoopers Service Delivery Center (Kolkata) Private Limited | K37: DLF Cyber Greens - Tower D & E, 6th Floor | L37: Operations | M37: Food & Beverages | N37: 46051.333 | O37: No | P37: What: Coffee machine and Water dispenser are not working. How: Power supply issue for the machine and dispenser. REQUESTER - Yastika Sikka | Q37: On-site MST has temporarily resolved the same. The wiring will be changed by vendor this weekend. - Close | R37: Closed | S37: Ravi | T37: 46051.406 | U37: Ravi | V37: 46051.406
A38: Gurugram | B38: Two Horizon | C38: 28-Jan-26 | D38: Jan'26 | E38: 42 | F38: 30 + Days | G38: 0 | H38: 2160 | I38: INC_TH10_TBS_2160 | J38: Alphagrep Securities | K38: Two Horizon 10th Floor | L38: Engineering & Building Services | M38: Plumbing | N38: 46050.438 | O38: No | P38: What: Sprinkler line leakage from the SS flexible joint Where: Near pantry area How: Not specified Requester: Sonu | Q38: The in-house team has checked the water leakage and the building team has been notified to rectify the issue. - Close | R38: Closed | S38: Sree Prabhu | T38: 46050.656 | U38: Sree Prabhu | V38: 46050.656
A39: Noida | B39: DLF Tech Park | C39: 27-Jan-26 | D39: Jan'26 | E39: 43 | F39: 30 + Days | G39: 0 | H39: 2151 | I39: INC_DLFTP6_TBS_2151 | J39: Table Space | K39: DLF Tech Park, 6th Floor | L39: Engineering & Building Services | M39: Carpentry | N39: 46049.625 | O39: No | P39: What: chair suddenly broken while employee was seated on chair Requester: Pankaj Kumar | Q39: Defective chair quarantined and replaced; [X] similar chairs inspected with [Y] removed; fasteners retorqued; and asked vendor to replace all the similar types of chairs - Close | R39: Closed | S39: Sree Prabhu | T39: 46049.779 | U39: Sree Prabhu | V39: 46049.779
A40: Gurugram | B40: DLF 6 | C40: 26-Jan-26 | D40: Jan'26 | E40: 44 | F40: 30 + Days | G40: 0 | H40: 2148 | I40: INC_DLFCB64_TBS_2148 | J40: ETS India | K40: DLF Cyber City, Building 6, 4th Floor | L40: Engineering & Building Services | M40: Electrical | N40: 46048.819 | O40: No | P40: What: UPS display is faulty. REQUESTER - Sonu Kumar Giri | Q40: The in-house team has checked the UPS display, and the UPS vendor has been aligned for repair/resolution. - Close | R40: Closed | S40: Ravi | T40: 46049.412 | U40: Ravi | V40: 46049.412
A41: Noida | B41: Capital City BPTP | C41: 26-Jan-26 | D41: Jan'26 | E41: 44 | F41: 30 + Days | G41: 0 | H41: 2147 | I41: INC_BPTPCC10_TBS_2147 | J41: Clearwater Analytics | K41: BPTP Capital City, 10th Floor | L41: Security | M41: Unauthorized Access | N41: 46048.521 | O41: No | P41: What: Police officers visit on operational floor at Republic Day. There was an unannounced visit by police officers in the mentioned premise at BPTP Capital city over a complaint raised through 112 - Police Helpline by Clearwater team stating that the office was operational on a public holiday. The police officers were allowed into the operational floor without any prior intimidation to the Tablespace Administration team . The police officers have further connected with the admin team of Clearwater Analytics and will investigate further in correspondence with the occurred incident. REQUESTER - Auroshikha Das | Q41: Tenants will be reminded to ensure that all statutory compliance documents, including wage slips, statutory approvals, and holiday declarations, are readily available during public holiday operations. Clearwater Analytics shared employee wage slips and other compliance-related documents with the police. Initial verification confirmed that wage payments and holiday-related compliances were in order. Police officers coordinated directly with the Clearwater administrative team for further review and investigation. - Close | R41: Closed | S41: Ravi | T41: 46049.409 | U41: Ravi | V41: 46049.409
A42: Noida | B42: DLF Tech Park | C42: 25-Jan-26 | D42: Jan'26 | E42: 45 | F42: 30 + Days | G42: 0 | H42: 2145 | I42: INC_DLFTP5_TBS_2145 | J42: Topsoe India Private Limited | K42: DLF Tech Park, 5th Floor | L42: Engineering & Building Services | M42: Electrical | N42: 46047.458 | O42: No | P42: What: RCCB found melted. How: During the yearly planned shutdown activity, the in-house team inspected the electrical system and identified that the RCCB feeding the Topsoe server rack had melted. REQUESTER - Anoop Singh | Q42: 1-The damaged RCCB was immediately replaced with a new RCCB of the same rating. 2-All terminal connections of the new RCCB were properly tightened as per manufacturer torque specifications. 3-A detailed inspection of the associated server rack power connections was carried out to ensure no further abnormalities. 4-Periodic preventive maintenance checks, including torque verification of critical electrical connections, have been added to the maintenance schedule to prevent recurrence. - Close | R42: Closed | S42: Ravi | T42: 46049.397 | U42: Ravi | V42: 46049.397
A43: Gurugram | B43: Cyber Green | C43: 24-Jan-26 | D43: Jan'26 | E43: 46 | F43: 30 + Days | G43: 0 | H43: 2141 | I43: INC_DLFCG7_TBS_2141 | J43: Table Space | K43: DLF Cyber Greens - Tower D & E, 7th Floor | L43: Engineering & Building Services | M43: Safety security systems | N43: 46046.521 | O43: No | P43: False alarm activated. What: smoke detector activated. REQUESTER - Yastika Sikka | Q43: In-house MST checked the smoke detector, which was activated due to dust, now working normal. - Close | R43: Closed | S43: Ravi | T43: 46046.566 | U43: Ravi | V43: 46046.566
A44: Gurugram | B44: DLF 10 B&C | C44: 23-Jan-26 | D44: Jan'26 | E44: 47 | F44: 30 + Days | G44: 0 | H44: 2137 | I44: INC_DLFCC10B14_TBS_2137 | J44: Tresvista | K44: DLF Cyber City 10B&C, 14th Floor | L44: Engineering & Building Services | M44: Civil | N44: 46045.868 | O44: No | P44: Water leakage from the ceiling *Where*:Workstation area *How*: There was the leakage from the terrace Requester: Sonu | Q44: The in-house team had checked the ceiling and water is coming from the terrace we have informed the Building team to rectify the water leakage issue - Close | R44: Closed | S44: Sree Prabhu | T44: 46046.397 | U44: Sree Prabhu | V44: 46046.397
A45: Noida | B45: Capital City BPTP | C45: 22-Jan-26 | D45: Jan'26 | E45: 48 | F45: 30 + Days | G45: 0 | H45: 2129 | I45: INC_BPTPCC15_TBS_2129 | J45: Nimbuspay Innovations India Private Limited | K45: BPTP Capital City, 15th Floor | L45: Health & Safety | M45: Medical Emergencies | N45: 46044.444 | O45: No | P45: What: The incident occurred near the car parking lift. How: The associate was standing near the car parking lift and checking his wallet. During that time, the lift button was pressed. The valet service staff assumed that no associate was standing near the lift, which led to the incident and caused a minor scratch injury. The associate sustained a minor scratch on the toes REQUESTER - Vishwajeet Kumar Singh | Q45: We have highlighted the issue to the builder and clearly said Instruct valet service staff to ensure clear visual confirmation of the lift area before pressing the lift button. Conduct a safety briefing/training for all valet and support staff on safe lift operation and awareness of surrounding personnel. Install clear safety signage near the car parking lift area indicating “Check Area Before Operating Lift.” Assign defined standing zones near the lift to prevent associates from standing too close during operation. - Close | R45: Closed | S45: Ravi | T45: 46044.508 | U45: Ravi | V45: 46044.508
A46: Gurugram | B46: Good Earth Business Bay II | C46: 20-Jan-26 | D46: Jan'26 | E46: 50 | F46: 30 + Days | G46: 0 | H46: 2124 | I46: INC_GOBB23_TBS_2124 | J46: BAYSTREET ADVISORS PRIVATE LIMITED | K46: Good Earth Business Bay II, 3rd Floor | L46: Engineering & Building Services | M46: Electrical | N46: 46042.75 | O46: No | P46: What: Internet connectivity outage. How: Under investigation. REQUESTER - Shweta sharma | Q46: Aakash Pandey - Close | R46: Closed | S46: Ravi | T46: 46043.728 | U46: Ravi | V46: 46043.728
... A87: Gurugram | B87: DLF 10 B&C | C87: 05-Dec-25 | D87: Dec'25 | E87: 96 | F87: 30 + Days | G87: 0 | H87: 1921 | I87: INC_DLFBCC10_TBS_1921 | J87: Baker Hughes | K87: DLF Cyber City - Building No. 10 - Tower B & C, 10th Floor | L87: Engineering & Building Services | M87: Plumbing | N87: 45996.312 | O87: Yes | P87: Water dripping/seepage observed through the ceiling in both Ladies’ and Gents’ washrooms. How: Water leakage was identified coming from the ceiling in both washrooms. The leak appears to be originating from construction/renovation activities taking place on the 11th floor above the affected location. requester: Jetin Negi | Q87: DLF team corrected the damage - Close | R87: Closed | S87: Sree Prabhu | T87: 45996.469 | U87: Sree Prabhu | V87: 45996.469
A88: Gurugram | B88: DLF 10 B&C | C88: 04-Dec-25 | D88: Dec'25 | E88: 97 | F88: 30 + Days | G88: 1 | H88: 1918 | I88: INC_DLFBCC3_TBS_1918 | J88: Table Space | K88: DLF Cyber City 10B&C, 3rd Floor | L88: Engineering & Building Services | M88: Electrical | N88: 45995.764 | O88: No | P88: Printer provided to the client faced an interruption in service Where: 3rd Floor How: The invoices need to be raised for the vendor Requester: Gautami Choithwani | R88: Open | S88: Sree Prabhu | T88: 45996.455 | U88: Sree Prabhu | V88: 45996.455
A89: Gurugram | B89: DLF 10 B&C | C89: 04-Dec-25 | D89: Dec'25 | E89: 97 | F89: 30 + Days | G89: 0 | H89: 1916 | I89: INC_DLFBCC10_TBS_1916 | J89: SSandC | K89: DLF Cyber City - Building No. 10 - Tower B & C, 10th Floor | L89: Engineering & Building Services | M89: Safety security systems | N89: 45995.625 | O89: No | P89: What*: Smoke detector activated *Where*: 10th Floor *How*: Due to dust *Impact*: No impact | Q89: The team checked the smoke detector and found that it was activated due to dust. The detector has been cleaned, and the panel is now working properly. - Close | R89: Closed | S89: Nivedita MC | T89: 45995.889 | U89: Nivedita MC | V89: 45995.889
A90: Gurugram | B90: DLF 10 B&C | C90: 04-Dec-25 | D90: Dec'25 | E90: 97 | F90: 30 + Days | G90: 0 | H90: 1913 | I90: INC_DLFCC10BC_TBS_1913 | J90: Table Space | K90: DLF Cyber City 10B&C | L90: Engineering & Building Services | M90: Plumbing | N90: 45995.5 | O90: No | P90: What: Watet leakage observed in the handicap washroom from the ceiling How: Due to ongoing construction work in the upper floor | Q90: The builder has been contacted to provide resolution. - Close | R90: Closed | S90: Nivedita MC | T90: 45995.881 | U90: Nivedita MC | V90: 45995.881
A91: Gurugram | B91: DLF 10 B&C | C91: 04-Dec-25 | D91: Dec'25 | E91: 97 | F91: 30 + Days | G91: 0 | H91: 1910 | I91: INC_DLFCC10BC_TBS_1910 | J91: Table Space | K91: DLF Cyber City 10B&C | L91: Engineering & Building Services | M91: Plumbing | N91: 45995.479 | O91: No | P91: *What* : Urinals in the gent's washroom are blocked *How* : There is a blockage in the urinal due to blockage in the drain line. | Q91: Blockage was removed manually from the second floor WC line. Fire pressure treatment was also done. HK staff has been properly briefed and trained to prevent such cases from happening and a prevantative process has been communicated. - Close | R91: Closed | S91: Nivedita MC | T91: 45995.874 | U91: Nivedita MC | V91: 45995.874
A92: Noida | B92: Capital City BPTP | C92: 04-Dec-25 | D92: Dec'25 | E92: 97 | F92: 30 + Days | G92: 0 | H92: 1909 | I92: INC_BPTPCC9_TBS_1909 | J92: Naviga | K92: BPTP Capital City, 9th Floor | L92: Others | M92: Others | N92: 45995.583 | O92: No | P92: What: Misuse of the Naviga photocopy machine by a Table Space security staff member. How: The individual was not aware that the photocopy machine belonged to the client (Naviga) | Q92: The concerned security guard was counseled and warned regarding the misuse of client property. The security team was briefed about strict adherence to authorization protocols. A short awareness session was conducted for all ground staff, clearly instructing them not to use any client-owned machines, tools, or materials without formal approval. The incident was logged for internal compliance monitoring. - Close | R92: Closed | S92: Nivedita MC | T92: 45995.872 | U92: Nivedita MC | V92: 45995.872
A93: Gurugram | B93: Cyber Green | C93: 03-Dec-25 | D93: Dec'25 | E93: 98 | F93: 30 + Days | G93: 0 | H93: 1908 | I93: INC_DLFCG10_TBS_1908 | J93: Alight Solutions | K93: DLF Cyber Greens - Tower D & E, 10th Floor | L93: Operations | M93: Pest Control | N93: 45994.562 | O93: No | P93: Cockroach spotted on workstation, how: Under investigation: REQUESTER - Yastika Sikka | Q93: Pest control and sanitization has been done - Close | R93: Closed | S93: Ravi | T93: 45995.407 | U93: Ravi | V93: 45995.407
A94: Gurugram | B94: DLF 10 B&C | C94: 02-Dec-25 | D94: Dec'25 | E94: 99 | F94: 30 + Days | G94: 0 | H94: 1900 | I94: INC_DLFBCC3_TBS_1900 | J94: Table Space | K94: DLF Cyber City 10B&C, 3rd Floor | L94: Engineering & Building Services | M94: Electrical | N94: 45993.417 | O94: Yes | P94: Emergency UPS output supply was tripped Requester: Sonu Kumar Giri | Q94: OEM had checked the UPS and found that it was a short circuit on the output breaker. The team had identified with the OEM and resolved the issue, but the system has been kept under observation for 24 hours. - Close | R94: Closed | S94: Sree Prabhu | T94: 45993.617 | U94: Sree Prabhu | V94: 45993.617
A95: Gurugram | B95: DLF 10 B&C | C95: 02-Dec-25 | D95: Dec'25 | E95: 99 | F95: 30 + Days | G95: 0 | H95: 1899 | I95: INC_DLF10BF9_TBS_1899 | J95: Circle K | K95: DLF Cyber City 10B&C, 9th floor | L95: Engineering & Building Services | M95: Electrical | N95: 45993.444 | O95: No | P95: The dishwasher in the pantry is not working How : Certain parts are faulty Requester: Yuktha Manthpal | Q95: The faulty parts were replaced - Close | R95: Closed | S95: Sree Prabhu | T95: 45993.615 | U95: Sree Prabhu | V95: 45993.615
A96: Noida | B96: Capital City BPTP | C96: 27-Nov-25 | D96: Nov'25 | E96: 104 | F96: 30 + Days | G96: 0 | H96: 1883 | I96: INC_BPTPCC9_TBS_1883 | J96: Naviga | K96: BPTP Capital City, 9th Floor | L96: Engineering & Building Services | M96: Electrical | N96: 45988 | O96: No | P96: PFC card failure in Module No. 4 of the 100kVA KEOR MOD UPS How : Root Cause Analysis (RCA) is awaited from the OEM vendor partner (Numeric) Requester: Vishwajeet | Q96: The faulty Module No. 4 has been replaced with a new module. The issue has been escalated to the OEM (Numeric) for detailed testing and confirmation of root cause. Internal management has already been informed regarding the failure and replacement.Request OEM Numeric to conduct a detailed root cause analysis (RCA) of the failed PFC card. Perform regular thermal checks, dust cleaning, and preventive maintenance of PFC boards. Ensure stable input power supply and check for any incoming surge issues. Keep spare modules/cards available for immediate replacement in future. - Close | R96: Closed | S96: Sree Prabhu | T96: 45989.403 | U96: Sree Prabhu | V96: 45989.403
...
